Workbook

Sheet README
A1: ICE vs EV — Company Lease Comparison Workbook
A3: How this workbook is organized
A4: • Assumptions — every editable input (lease rate, residual %, tax, fuel/electricity cost, driving pattern, maintenance & insurance). Blue cells are yours to change; everything downstream recalculates.
A5: • Cars — the master list of vehicles. Prefilled rows 5-18 (14 cars). Rows 21-30 are blank — add your own car there (Type, Make & Model, Trim, On-road Price, and Mileage in kmpl for ICE / Efficiency in kWh per 100km for EV). It flows into every calculation automatically, no other sheet needs editing.
A6: • Lease Comparison — the engine. For every car and every lease tenure (3/4/5 years, 10% interest, 10% residual buyout as you specified) it computes: monthly EMI, total running cost (fuel/energy), maintenance + insurance, tax saved via the CTC carve-out, raw cash outflow, net cost after the tax shield, and cost per km. Rank columns at the far right (AB/AC/AD) show 1 = cheapest for that tenure.
A7: • Summary — condensed view: on-road price, net cost at 3/4/5 years, and rank, one row per car, for a quick scan.
A9: What I added beyond your list (flagged so you can remove them if you'd rather not see them)
A10: • Tata Nexon EV (45kWh) — direct same-model ICE-vs-EV pair with your Nexon Automatic, which is really the cleanest apples-to-apples comparison in this whole set.
A11: • Maruti e Vitara (Alpha 61kWh) and Kia Syros EV (HTX+ ER 51.4kWh) — both were on your shortlist in earlier sessions and I kept them in for continuity. Syros EV is very newly launched (Jul 2026) with no ownership track record yet — same caveat as before.
A12: • A raw cash outflow line alongside net cost after tax — so you can see what actually leaves your pocket before the tax-shield adjustment, not just the tax-adjusted number.
A13: • An EMI-vs-cap check — the EMI cell turns red if it would exceed your ₹60,000/month cap at that tenure.
A14: • A Sensitivity sheet — for each EV, the annual km at which it overtakes a reference ICE car (Nexon ICE by default, change the row number in cell D4 to compare against any other car) on net cost after tax.
... A23: • On-road prices for cars other than your two are estimated from ex-showroom + typical state markup — flagged per row. Get dealer quotes for your final shortlist.

Sheet Assumptions
A1: Assumptions
A2: Blue cells are editable inputs. Every formula in this workbook traces back to a cell on this sheet.
A4: Lease Terms
A5: Lease interest rate (p.a.) | B5: 0.1 | C5: %
A6: Residual value / buyout (%) | B6: 0.1 | C6: %
A7: Tenures modeled: 3, 4 and 5 years — set as fixed column headers on the Lease Comparison sheet.
A9: Income Tax (new regime)
A10: Income tax slab rate | B10: 0.3 | C10: %
A11: Health & education cess | B11: 0.04 | C11: %
A12: Combined marginal rate (computed) | B12: =B10*(1+B11) -> 0.312 | C12: %
A13: Motor car perquisite value (flat, FY26 rules) | B13: 5000 | C13: ₹/month | D13: Flat regardless of car price — this is why the tax benefit scales with EMI size, not with the car chosen.
A14: Company EMI cap | B14: 60000 | C14: ₹/month
A16: Fuel & Electricity Cost
A17: Petrol price | B17: 117 | C17: ₹/litre | D17: Hyderabad, Aug 2026
A18: Home charging cost (blended slab rate) | B18: 8 | C18: ₹/unit
A19: Public fast-charging cost | B19: 20 | C19: ₹/unit
A21: Driving Pattern
A22: Annual city driving | B22: 8000 | C22: km
A23: Annual highway driving | B23: 4000 | C23: km
A24: Total annual km (computed) | B24: =B22+B23 -> 12000 | C24: km
A25: ICE highway mileage multiplier (vs city) | B25: 1.35 | C25: × | D25: Highway kmpl assumed 35% better than city, steady-speed running.
A26: EV highway efficiency multiplier (vs city) | B26: 1.15 | C26: × | D26: Highway kWh/100km assumed 15% worse than city — aero drag dominates at speed.
A27: EV annual mileage multiplier | B27: 1 | C27: × | D27: Set >1.00 to model driving an EV more than the baseline km above (lower running cost can nudge usage up). E.g. 1.15 = drive 15% more km/year in an EV than in an ICE. Applies to EV rows only — ICE rows always use the baseline city/highway km. Leave at 1.00 for an apples-to-apples comparison.
A29: Maintenance & Insurance
A30: ICE annual maintenance | B30: 9000 | C30: ₹/year
A31: EV annual maintenance | B31: 4500 | C31: ₹/year
A32: ICE insurance rate (% of on-road price, yr 1) | B32: 0.03 | C32: %
A33: EV insurance rate (% of on-road price, yr 1) | B33: 0.038 | C33: % | D33: Higher than ICE — battery cover pushes up premiums.
A34: Annual insurance-base (IDV) depreciation rate | B34: 0.15 | C34: %

Sheet Cars
A1: Cars — Master List
A2: 14 prefilled cars below. Rows 21-30 are blank for your own entries — fill Type / Make & Model / Trim / On-road Price / Mileage-Efficiency and the Lease Comparison + Summary sheets pick it up automatically.
A4: # | B4: Type | C4: Make & Model | D4: Trim | E4: On-road Price (₹) | F4: Mileage (kmpl, ICE) / Efficiency (kWh/100km, EV) | G4: 360° Camera | H4: Notes / Source
A5: 1 | B5: ICE | C5: Tata Nexon | D5: Petrol Creative DCT (Automatic) | E5: 1328000 | F5: 10 | G5: Y | H5: Ex-showroom ₹11.25L (Autocar India) + ~17% Telangana on-road markup. Mileage = your real-world city figure on the 2020 manual, applied to the DCT (ARAI DCT is close to manual anyway).
A6: 2 | B6: ICE | C6: Hyundai Creta | D6: SX Tech iVT Petrol (360° cam) | E6: 1979000 | F6: 10 | G6: Y | H6: On-road Delhi ₹19.79L (CarDekho, ARAI 17.7 kmpl). Mileage derated to ~57% of ARAI using the ratio from your own Nexon experience — treat as a rough proxy, not owner data for this car.
A7: 3 | B7: ICE | C7: Mahindra XUV 3XO | D7: AX5L TGDi Automatic | E7: 1758000 | F7: 9.5 | G7: Y | H7: On-road Delhi ₹17.58L (AckoDrive). Mileage is an actual owner-reported city figure (CarWale review) — one of the few real-world data points in this list.
A8: 4 | B8: ICE | C8: Mahindra XUV 3XO | D8: AX7L TGDi Automatic (top) | E8: 1785000 | F8: 10 | G8: Y | H8: On-road ~₹17.85L (CarWale upper band). Mileage estimated close to AX5L — same 1.2L turbo-petrol engine and tune, no separate owner data found.
A9: 5 | B9: ICE | C9: Honda Elevate | D9: ZX CVT Automatic (360° cam via Lite Pack) | E9: 1865000 | F9: 11 | G9: Y | H9: On-road Delhi ₹18.65L (CarDekho). Mileage = midpoint of an owner-reported city range of 10-12 kmpl (CarWale review).
A10: 6 | B10: EV | C10: Tata Curvv EV | D10: Accomplished X, 55kWh | E10: 1775000 | F10: 14 | G10: Y | H10: Your quoted on-road price. Efficiency estimated from real-world range 380-400km on 55kWh (Cars24).
A11: 7 | B11: EV | C11: Hyundai Creta Electric | D11: Excellence, 42kWh (360° cam) | E11: 2250000 | F11: 13.5 | G11: Y | H11: On-road ₹22.50L (91Wheels). Efficiency from real-world city range 300-320km (Cars24).
A12: 8 | B12: EV | C12: Hyundai Creta Electric | D12: Excellence LR, 51.4kWh (360° cam) | E12: 2530000 | F12: 13.9 | G12: Y | H12: Ex-showroom ₹23.67L (CarDekho) + ~7% on-road estimate (EVs get lower road-tax markup than ICE in most states). Efficiency from real-world range 360-380km (Cars24).
A13: 9 | B13: EV | C13: MG Windsor EV | D13: Essence Pro, 52.9kWh (360° cam) | E13: 1980000 | F13: 13.2 | G13: Y | H13: Ex-showroom ~₹18.10-19.00L + ~7% on-road estimate. Efficiency from MG's own reported 400+km real-world range on the 52.9kWh pack.
A14: 10 | B14: EV | C14: Mahindra XUV 3XO EV | D14: AX7L (top, 360° cam standard) | E14: 1643000 | F14: 13.8 | G14: Y | H14: On-road Mumbai ₹16.43L (CarWale). Efficiency from Mahindra's own real-world 285km claim on 39.4kWh.
A15: 11 | B15: EV | C15: Tata Sierra EV | D15: Adventure, 63kWh (360° cam trim) | E15: 2214000 | F15: 15.4 | G15: Y | H15: Ex-showroom ₹20.99L (CarDekho) + ~5.5% on-road estimate. Efficiency estimated from ARAI 566km derated to ~410km real-world city — brand new launch (Jun 2026), no owner data yet.
A16: 12 | B16: EV | C16: Tata Nexon EV | D16: Empowered+ A, 45kWh LR (360° cam) — ADDED | E16: 1946000 | F16: 14.1 | G16: Y | H16: ADDED for a direct same-model ICE-vs-EV comparison against your Nexon Automatic. Ex-showroom ₹17.69L (CarWale) + ~10% on-road estimate. Efficiency from real-world range 310-330km (CarDekho).
... A18: 14 | B18: EV | C18: Kia Syros EV | D18: HTX+ ER, 51.4kWh (360° cam) — ADDED | E18: 1950000 | F18: 13.5 | G18: Y | H18: ADDED — carried over from your earlier shortlist. Very new launch (Jul 2026), no ownership track record yet. Ex-showroom ~₹18L + ~8% on-road estimate. Efficiency estimated from platform-mate Creta Electric 51.4kWh.
A20: ADD YOUR OWN CAR BELOW — fill Type (ICE or EV), Make & Model, Trim, On-road Price, and Mileage/Efficiency. Leave 360° Camera and Notes blank if you like; nothing else needs to change.
A21: 17
A22: 18
A23: 19
A24: 20
A25: 21
A26: 22
A27: 23
A28: 24
A29: 25
A30: 26

Sheet Lease Comparison
A1: Lease Comparison — 3 / 4 / 5 Year Company Lease (10% interest, 10% residual buyout)
A2: All figures flow from Assumptions + Cars. Rank columns (AB/AC/AD): 1 = cheapest net cost for that tenure.
G4: 3-Year Lease | N4: 4-Year Lease | U4: 5-Year Lease | AB4: Rank by Net Cost (1 = cheapest)
A5: # | B5: Type | C5: Car | D5: Trim | E5: On-road Price (₹) | F5: Mileage/Efficiency | G5: Monthly EMI (₹) | H5: Total Running Cost (₹) | I5: Total Maint. + Insurance (₹) | J5: Total Tax Saved (₹) | K5: Raw Cash Outflow (₹) | L5: Net Cost After Tax (₹) | M5: Effective Cost / km (₹) | N5: Monthly EMI (₹) | O5: Total Running Cost (₹) | P5: Total Maint. + Insurance (₹) | Q5: Total Tax Saved (₹) | R5: Raw Cash Outflow (₹) | S5: Net Cost After Tax (₹) | T5: Effective Cost / km (₹) | U5: Monthly EMI (₹) | V5: Total Running Cost (₹) | W5: Total Maint. + Insurance (₹) | X5: Total Tax Saved (₹) | Y5: Raw Cash Outflow (₹) | Z5: Net Cost After Tax (₹) | AA5: Effective Cost / km (₹) | AB5: 3yr | AC5: 4yr | AD5: 5yr
A6: 1 | B6: =Cars!B5 -> ICE | C6: =Cars!C5 -> Tata Nexon | D6: =Cars!D5 -> Petrol Creative DCT (Automatic) | E6: =Cars!E5 -> 1328000 | F6: =Cars!F5 -> 10 | G6: =IF(ISBLANK(Cars!$E$5),"",PMT(Assumptions!$B$5/12,36,-$E6,$E6*Assumptions!$B$6)) -> 39672.409 | H6: =IF(ISBLANK(Cars!$E$5),"",(IF($B6="ICE",Assumptions!$B$22/$F6*Assumptions!$B$17+Assumptions!$B$23/($F6*Assumptions!$B$25)*Assumptions!$B$17,Assumptions!$B$22*Assumptions!$B$27*($F6/100)*Assumptions!$B$18+Assumptions!$B$23*Assumptions!$B$27*($F6*Assumptions!$B$26/100)*Assumptions!$B$19))*3) -> 384800 | I6: =IF(ISBLANK(Cars!$E$5),"",(IF($B6="ICE",Assumptions!$B$30,Assumptions!$B$31)*3)+($E6*IF($B6="ICE",Assumptions!$B$32,Assumptions!$B$33)*(1-(1-Assumptions!$B$34)^3)/Assumptions!$B$34)) -> 129488.4 | J6: =IF(ISBLANK(Cars!$E$5),"",Assumptions!$B$12*(G6-Assumptions!$B$13)*36) -> 389440.5 | K6: =IF(ISBLANK(Cars!$E$5),"",G6*36+$E6*Assumptions!$B$6+H6+I6) -> 2075295.1 | L6: =IF(ISBLANK(Cars!$E$5),"",K6-J6) -> 1685854.6 | M6: =IF(ISBLANK(Cars!$E$5),"",L6/(Assumptions!$B$24*IF($B6="EV",Assumptions!$B$27,1)*3)) -> 46.829295 | N6: =IF(ISBLANK(Cars!$E$5),"",PMT(Assumptions!$B$5/12,48,-$E6,$E6*Assumptions!$B$6)) -> 31420.026 | O6: =IF(ISBLANK(Cars!$E$5),"",(IF($B6="ICE",Assumptions!$B$22/$F6*Assumptions!$B$17+Assumptions!$B$23/($F6*Assumptions!$B$25)*Assumptions!$B$17,Assumptions!$B$22*Assumptions!$B$27*($F6/100)*Assumptions!$B$18+Assumptions!$B$23*Assumptions!$B$27*($F6*Assumptions!$B$26/100)*Assumptions!$B$19))*4) -> 513066.67 | P6: =IF(ISBLANK(Cars!$E$5),"",(IF($B6="ICE",Assumptions!$B$30,Assumptions!$B$31)*4)+($E6*IF($B6="ICE",Assumptions!$B$32,Assumptions!$B$33)*(1-(1-Assumptions!$B$34)^4)/Assumptions!$B$34)) -> 162955.14 | Q6: =IF(ISBLANK(Cars!$E$5),"",Assumptions!$B$12*(N6-Assumptions!$B$13)*48) -> 395666.32 | R6: =IF(ISBLANK(Cars!$E$5),"",N6*48+$E6*Assumptions!$B$6+O6+P6) -> 2316983.1 | S6: =IF(ISBLANK(Cars!$E$5),"",R6-Q6) -> 1921316.8 | T6: =IF(ISBLANK(Cars!$E$5),"",S6/(Assumptions!$B$24*IF($B6="EV",Assumptions!$B$27,1)*4)) -> 40.027432 | U6: =IF(ISBLANK(Cars!$E$5),"",PMT(Assumptions!$B$5/12,60,-$E6,$E6*Assumptions!$B$6)) -> 26501.135 | V6: =IF(ISBLANK(Cars!$E$5),"",(IF($B6="ICE",Assumptions!$B$22/$F6*Assumptions!$B$17+Assumptions!$B$23/($F6*Assumptions!$B$25)*Assumptions!$B$17,Assumptions!$B$22*Assumptions!$B$27*($F6/100)*Assumptions!$B$18+Assumptions!$B$23*Assumptions!$B$27*($F6*Assumptions!$B$26/100)*Assumptions!$B$19))*5) -> 641333.33 | W6: =IF(ISBLANK(Cars!$E$5),"",(IF($B6="ICE",Assumptions!$B$30,Assumptions!$B$31)*5)+($E6*IF($B6="ICE",Assumptions!$B$32,Assumptions!$B$33)*(1-(1-Assumptions!$B$34)^5)/Assumptions!$B$34)) -> 192751.87 | X6: =IF(ISBLANK(Cars!$E$5),"",Assumptions!$B$12*(U6-Assumptions!$B$13)*60) -> 402501.24 | Y6: =IF(ISBLANK(Cars!$E$5),"",U6*60+$E6*Assumptions!$B$6+V6+W6) -> 2556953.3 | Z6: =IF(ISBLANK(Cars!$E$5),"",Y6-X6) -> 2154452 | AA6: =IF(ISBLANK(Cars!$E$5),"",Z6/(Assumptions!$B$24*IF($B6="EV",Assumptions!$B$27,1)*5)) -> 35.907534 | AB6: =IF(ISBLANK(Cars!$E$5),"",RANK(L6,$L$6:$L$31,1)) -> 2 | AC6: =IF(ISBLANK(Cars!$E$5),"",RANK(S6,$S$6:$S$31,1)) -> 2 | AD6: =IF(ISBLANK(Cars!$E$5),"",RANK(Z6,$Z$6:$Z$31,1)) -> 3
A7: 2 | B7: =Cars!B6 -> ICE | C7: =Cars!C6 -> Hyundai Creta | D7: =Cars!D6 -> SX Tech iVT Petrol (360° cam) | E7: =Cars!E6 -> 1979000 | F7: =Cars!F6 -> 10 | G7: =IF(ISBLANK(Cars!$E$6),"",PMT(Assumptions!$B$5/12,36,-$E7,$E7*Assumptions!$B$6)) -> 59120.254 | H7: =IF(ISBLANK(Cars!$E$6),"",(IF($B7="ICE",Assumptions!$B$22/$F7*Assumptions!$B$17+Assumptions!$B$23/($F7*Assumptions!$B$25)*Assumptions!$B$17,Assumptions!$B$22*Assumptions!$B$27*($F7/100)*Assumptions!$B$18+Assumptions!$B$23*Assumptions!$B$27*($F7*Assumptions!$B$26/100)*Assumptions!$B$19))*3) -> 384800 | I7: =IF(ISBLANK(Cars!$E$6),"",(IF($B7="ICE",Assumptions!$B$30,Assumptions!$B$31)*3)+($E7*IF($B7="ICE",Assumptions!$B$32,Assumptions!$B$33)*(1-(1-Assumptions!$B$34)^3)/Assumptions!$B$34)) -> 179729.33 | J7: =IF(ISBLANK(Cars!$E$6),"",Assumptions!$B$12*(G7-Assumptions!$B$13)*36) -> 607878.69 | K7: =IF(ISBLANK(Cars!$E$6),"",G7*36+$E7*Assumptions!$B$6+H7+I7) -> 2890758.5 | L7: =IF(ISBLANK(Cars!$E$6),"",K7-J7) -> 2282879.8 | M7: =IF(ISBLANK(Cars!$E$6),"",L7/(Assumptions!$B$24*IF($B7="EV",Assumptions!$B$27,1)*3)) -> 63.413327 | N7: =IF(ISBLANK(Cars!$E$6),"",PMT(Assumptions!$B$5/12,48,-$E7,$E7*Assumptions!$B$6)) -> 46822.464 | O7: =IF(ISBLANK(Cars!$E$6),"",(IF($B7="ICE",Assumptions!$B$22/$F7*Assumptions!$B$17+Assumptions!$B$23/($F7*Assumptions!$B$25)*Assumptions!$B$17,Assumptions!$B$22*Assumptions!$B$27*($F7/100)*Assumptions!$B$18+Assumptions!$B$23*Assumptions!$B$27*($F7*Assumptions!$B$26/100)*Assumptions!$B$19))*4) -> 513066.67 | P7: =IF(ISBLANK(Cars!$E$6),"",(IF($B7="ICE",Assumptions!$B$30,Assumptions!$B$31)*4)+($E7*IF($B7="ICE",Assumptions!$B$32,Assumptions!$B$33)*(1-(1-Assumptions!$B$34)^4)/Assumptions!$B$34)) -> 225189.93 | Q7: =IF(ISBLANK(Cars!$E$6),"",Assumptions!$B$12*(N7-Assumptions!$B$13)*48) -> 626333.22 | R7: =IF(ISBLANK(Cars!$E$6),"",N7*48+$E7*Assumptions!$B$6+O7+P7) -> 3183634.9 | S7: =IF(ISBLANK(Cars!$E$6),"",R7-Q7) -> 2557301.6 | T7: =IF(ISBLANK(Cars!$E$6),"",S7/(Assumptions!$B$24*IF($B7="EV",Assumptions!$B$27,1)*4)) -> 53.277118 | U7: =IF(ISBLANK(Cars!$E$6),"",PMT(Assumptions!$B$5/12,60,-$E7,$E7*Assumptions!$B$6)) -> 39492.278 | V7: =IF(ISBLANK(Cars!$E$6),"",(IF($B7="ICE",Assumptions!$B$22/$F7*Assumptions!$B$17+Assumptions!$B$23/($F7*Assumptions!$B$25)*Assumptions!$B$17,Assumptions!$B$22*Assumptions!$B$27*($F7/100)*Assumptions!$B$18+Assumptions!$B$23*Assumptions!$B$27*($F7*Assumptions!$B$26/100)*Assumptions!$B$19))*5) -> 641333.33 | W7: =IF(ISBLANK(Cars!$E$6),"",(IF($B7="ICE",Assumptions!$B$30,Assumptions!$B$31)*5)+($E7*IF($B7="ICE",Assumptions!$B$32,Assumptions!$B$33)*(1-(1-Assumptions!$B$34)^5)/Assumptions!$B$34)) -> 265181.44 | X7: =IF(ISBLANK(Cars!$E$6),"",Assumptions!$B$12*(U7-Assumptions!$B$13)*60) -> 645695.44 | Y7: =IF(ISBLANK(Cars!$E$6),"",U7*60+$E7*Assumptions!$B$6+V7+W7) -> 3473951.5 | Z7: =IF(ISBLANK(Cars!$E$6),"",Y7-X7) -> 2828256 | AA7: =IF(ISBLANK(Cars!$E$6),"",Z7/(Assumptions!$B$24*IF($B7="EV",Assumptions!$B$27,1)*5)) -> 47.1376 | AB7: =IF(ISBLANK(Cars!$E$6),"",RANK(L7,$L$6:$L$31,1)) -> 13 | AC7: =IF(ISBLANK(Cars!$E$6),"",RANK(S7,$S$6:$S$31,1)) -> 13 | AD7: =IF(ISBLANK(Cars!$E$6),"",RANK(Z7,$Z$6:$Z$31,1)) -> 13
A8: 3 | B8: =Cars!B7 -> ICE | C8: =Cars!C7 -> Mahindra XUV 3XO | D8: =Cars!D7 -> AX5L TGDi Automatic | E8: =Cars!E7 -> 1758000 | F8: =Cars!F7 -> 9.5 | G8: =IF(ISBLANK(Cars!$E$7),"",PMT(Assumptions!$B$5/12,36,-$E8,$E8*Assumptions!$B$6)) -> 52518.144 | H8: =IF(ISBLANK(Cars!$E$7),"",(IF($B8="ICE",Assumptions!$B$22/$F8*Assumptions!$B$17+Assumptions!$B$23/($F8*Assumptions!$B$25)*Assumptions!$B$17,Assumptions!$B$22*Assumptions!$B$27*($F8/100)*Assumptions!$B$18+Assumptions!$B$23*Assumptions!$B$27*($F8*Assumptions!$B$26/100)*Assumptions!$B$19))*3) -> 405052.63 | I8: =IF(ISBLANK(Cars!$E$7),"",(IF($B8="ICE",Assumptions!$B$30,Assumptions!$B$31)*3)+($E8*IF($B8="ICE",Assumptions!$B$32,Assumptions!$B$33)*(1-(1-Assumptions!$B$34)^3)/Assumptions!$B$34)) -> 162673.65 | J8: =IF(ISBLANK(Cars!$E$7),"",Assumptions!$B$12*(G8-Assumptions!$B$13)*36) -> 533723.79 | K8: =IF(ISBLANK(Cars!$E$7),"",G8*36+$E8*Assumptions!$B$6+H8+I8) -> 2634179.5 | L8: =IF(ISBLANK(Cars!$E$7),"",K8-J8) -> 2100455.7 | M8: =IF(ISBLANK(Cars!$E$7),"",L8/(Assumptions!$B$24*IF($B8="EV",Assumptions!$B$27,1)*3)) -> 58.345991 | N8: =IF(ISBLANK(Cars!$E$7),"",PMT(Assumptions!$B$5/12,48,-$E8,$E8*Assumptions!$B$6)) -> 41593.68 | O8: =IF(ISBLANK(Cars!$E$7),"",(IF($B8="ICE",Assumptions!$B$22/$F8*Assumptions!$B$17+Assumptions!$B$23/($F8*Assumptions!$B$25)*Assumptions!$B$17,Assumptions!$B$22*Assumptions!$B$27*($F8/100)*Assumptions!$B$18+Assumptions!$B$23*Assumptions!$B$27*($F8*Assumptions!$B$26/100)*Assumptions!$B$19))*4) -> 540070.18 | P8: =IF(ISBLANK(Cars!$E$7),"",(IF($B8="ICE",Assumptions!$B$30,Assumptions!$B$31)*4)+($E8*IF($B8="ICE",Assumptions!$B$32,Assumptions!$B$33)*(1-(1-Assumptions!$B$34)^4)/Assumptions!$B$34)) -> 204062.6 | Q8: =IF(ISBLANK(Cars!$E$7),"",Assumptions!$B$12*(N8-Assumptions!$B$13)*48) -> 548026.94 | R8: =IF(ISBLANK(Cars!$E$7),"",N8*48+$E8*Assumptions!$B$6+O8+P8) -> 2916429.4 | S8: =IF(ISBLANK(Cars!$E$7),"",R8-Q8) -> 2368402.5 | T8: =IF(ISBLANK(Cars!$E$7),"",S8/(Assumptions!$B$24*IF($B8="EV",Assumptions!$B$27,1)*4)) -> 49.341718 | U8: =IF(ISBLANK(Cars!$E$7),"",PMT(Assumptions!$B$5/12,60,-$E8,$E8*Assumptions!$B$6)) -> 35082.074 | V8: =IF(ISBLANK(Cars!$E$7),"",(IF($B8="ICE",Assumptions!$B$22/$F8*Assumptions!$B$17+Assumptions!$B$23/($F8*Assumptions!$B$25)*Assumptions!$B$17,Assumptions!$B$22*Assumptions!$B$27*($F8/100)*Assumptions!$B$18+Assumptions!$B$23*Assumptions!$B$27*($F8*Assumptions!$B$26/100)*Assumptions!$B$19))*5) -> 675087.72 | W8: =IF(ISBLANK(Cars!$E$7),"",(IF($B8="ICE",Assumptions!$B$30,Assumptions!$B$31)*5)+($E8*IF($B8="ICE",Assumptions!$B$32,Assumptions!$B$33)*(1-(1-Assumptions!$B$34)^5)/Assumptions!$B$34)) -> 240593.21 | X8: =IF(ISBLANK(Cars!$E$7),"",Assumptions!$B$12*(U8-Assumptions!$B$13)*60) -> 563136.43 | Y8: =IF(ISBLANK(Cars!$E$7),"",U8*60+$E8*Assumptions!$B$6+V8+W8) -> 3196405.4 | Z8: =IF(ISBLANK(Cars!$E$7),"",Y8-X8) -> 2633269 | AA8: =IF(ISBLANK(Cars!$E$7),"",Z8/(Assumptions!$B$24*IF($B8="EV",Assumptions!$B$27,1)*5)) -> 43.887816 | AB8: =IF(ISBLANK(Cars!$E$7),"",RANK(L8,$L$6:$L$31,1)) -> 7 | AC8: =IF(ISBLANK(Cars!$E$7),"",RANK(S8,$S$6:$S$31,1)) -> 9 | AD8: =IF(ISBLANK(Cars!$E$7),"",RANK(Z8,$Z$6:$Z$31,1)) -> 11
A9: 4 | B9: =Cars!B8 -> ICE | C9: =Cars!C8 -> Mahindra XUV 3XO | D9: =Cars!D8 -> AX7L TGDi Automatic (top) | E9: =Cars!E8 -> 1785000 | F9: =Cars!F8 -> 10 | G9: =IF(ISBLANK(Cars!$E$8),"",PMT(Assumptions!$B$5/12,36,-$E9,$E9*Assumptions!$B$6)) -> 53324.736 | H9: =IF(ISBLANK(Cars!$E$8),"",(IF($B9="ICE",Assumptions!$B$22/$F9*Assumptions!$B$17+Assumptions!$B$23/($F9*Assumptions!$B$25)*Assumptions!$B$17,Assumptions!$B$22*Assumptions!$B$27*($F9/100)*Assumptions!$B$18+Assumptions!$B$23*Assumptions!$B$27*($F9*Assumptions!$B$26/100)*Assumptions!$B$19))*3) -> 384800 | I9: =IF(ISBLANK(Cars!$E$8),"",(IF($B9="ICE",Assumptions!$B$30,Assumptions!$B$31)*3)+($E9*IF($B9="ICE",Assumptions!$B$32,Assumptions!$B$33)*(1-(1-Assumptions!$B$34)^3)/Assumptions!$B$34)) -> 164757.38 | J9: =IF(ISBLANK(Cars!$E$8),"",Assumptions!$B$12*(G9-Assumptions!$B$13)*36) -> 542783.44 | K9: =IF(ISBLANK(Cars!$E$8),"",G9*36+$E9*Assumptions!$B$6+H9+I9) -> 2647747.9 | L9: =IF(ISBLANK(Cars!$E$8),"",K9-J9) -> 2104964.4 | M9: =IF(ISBLANK(Cars!$E$8),"",L9/(Assumptions!$B$24*IF($B9="EV",Assumptions!$B$27,1)*3)) -> 58.471234 | N9: =IF(ISBLANK(Cars!$E$8),"",PMT(Assumptions!$B$5/12,48,-$E9,$E9*Assumptions!$B$6)) -> 42232.49 | O9: =IF(ISBLANK(Cars!$E$8),"",(IF($B9="ICE",Assumptions!$B$22/$F9*Assumptions!$B$17+Assumptions!$B$23/($F9*Assumptions!$B$25)*Assumptions!$B$17,Assumptions!$B$22*Assumptions!$B$27*($F9/100)*Assumptions!$B$18+Assumptions!$B$23*Assumptions!$B$27*($F9*Assumptions!$B$26/100)*Assumptions!$B$19))*4) -> 513066.67 | P9: =IF(ISBLANK(Cars!$E$8),"",(IF($B9="ICE",Assumptions!$B$30,Assumptions!$B$31)*4)+($E9*IF($B9="ICE",Assumptions!$B$32,Assumptions!$B$33)*(1-(1-Assumptions!$B$34)^4)/Assumptions!$B$34)) -> 206643.77 | Q9: =IF(ISBLANK(Cars!$E$8),"",Assumptions!$B$12*(N9-Assumptions!$B$13)*48) -> 557593.77 | R9: =IF(ISBLANK(Cars!$E$8),"",N9*48+$E9*Assumptions!$B$6+O9+P9) -> 2925370 | S9: =IF(ISBLANK(Cars!$E$8),"",R9-Q9) -> 2367776.2 | T9: =IF(ISBLANK(Cars!$E$8),"",S9/(Assumptions!$B$24*IF($B9="EV",Assumptions!$B$27,1)*4)) -> 49.328671 | U9: =IF(ISBLANK(Cars!$E$8),"",PMT(Assumptions!$B$5/12,60,-$E9,$E9*Assumptions!$B$6)) -> 35620.877 | V9: =IF(ISBLANK(Cars!$E$8),"",(IF($B9="ICE",Assumptions!$B$22/$F9*Assumptions!$B$17+Assumptions!$B$23/($F9*Assumptions!$B$25)*Assumptions!$B$17,Assumptions!$B$22*Assumptions!$B$27*($F9/100)*Assumptions!$B$18+Assumptions!$B$23*Assumptions!$B$27*($F9*Assumptions!$B$26/100)*Assumptions!$B$19))*5) -> 641333.33 | W9: =IF(ISBLANK(Cars!$E$8),"",(IF($B9="ICE",Assumptions!$B$30,Assumptions!$B$31)*5)+($E9*IF($B9="ICE",Assumptions!$B$32,Assumptions!$B$33)*(1-(1-Assumptions!$B$34)^5)/Assumptions!$B$34)) -> 243597.2 | X9: =IF(ISBLANK(Cars!$E$8),"",Assumptions!$B$12*(U9-Assumptions!$B$13)*60) -> 573222.82 | Y9: =IF(ISBLANK(Cars!$E$8),"",U9*60+$E9*Assumptions!$B$6+V9+W9) -> 3200683.2 | Z9: =IF(ISBLANK(Cars!$E$8),"",Y9-X9) -> 2627460.4 | AA9: =IF(ISBLANK(Cars!$E$8),"",Z9/(Assumptions!$B$24*IF($B9="EV",Assumptions!$B$27,1)*5)) -> 43.791006 | AB9: =IF(ISBLANK(Cars!$E$8),"",RANK(L9,$L$6:$L$31,1)) -> 8 | AC9: =IF(ISBLANK(Cars!$E$8),"",RANK(S9,$S$6:$S$31,1)) -> 8 | AD9: =IF(ISBLANK(Cars!$E$8),"",RANK(Z9,$Z$6:$Z$31,1)) -> 10
A10: 5 | B10: =Cars!B9 -> ICE | C10: =Cars!C9 -> Honda Elevate | D10: =Cars!D9 -> ZX CVT Automatic (360° cam via Lite Pack) | E10: =Cars!E9 -> 1865000 | F10: =Cars!F9 -> 11 | G10: =IF(ISBLANK(Cars!$E$9),"",PMT(Assumptions!$B$5/12,36,-$E10,$E10*Assumptions!$B$6)) -> 55714.64 | H10: =IF(ISBLANK(Cars!$E$9),"",(IF($B10="ICE",Assumptions!$B$22/$F10*Assumptions!$B$17+Assumptions!$B$23/($F10*Assumptions!$B$25)*Assumptions!$B$17,Assumptions!$B$22*Assumptions!$B$27*($F10/100)*Assumptions!$B$18+Assumptions!$B$23*Assumptions!$B$27*($F10*Assumptions!$B$26/100)*Assumptions!$B$19))*3) -> 349818.18 | I10: =IF(ISBLANK(Cars!$E$9),"",(IF($B10="ICE",Assumptions!$B$30,Assumptions!$B$31)*3)+($E10*IF($B10="ICE",Assumptions!$B$32,Assumptions!$B$33)*(1-(1-Assumptions!$B$34)^3)/Assumptions!$B$34)) -> 170931.38 | J10: =IF(ISBLANK(Cars!$E$9),"",Assumptions!$B$12*(G10-Assumptions!$B$13)*36) -> 569626.84 | K10: =IF(ISBLANK(Cars!$E$9),"",G10*36+$E10*Assumptions!$B$6+H10+I10) -> 2712976.6 | L10: =IF(ISBLANK(Cars!$E$9),"",K10-J10) -> 2143349.8 | M10: =IF(ISBLANK(Cars!$E$9),"",L10/(Assumptions!$B$24*IF($B10="EV",Assumptions!$B$27,1)*3)) -> 59.537494 | N10: =IF(ISBLANK(Cars!$E$9),"",PMT(Assumptions!$B$5/12,48,-$E10,$E10*Assumptions!$B$6)) -> 44125.263 | O10: =IF(ISBLANK(Cars!$E$9),"",(IF($B10="ICE",Assumptions!$B$22/$F10*Assumptions!$B$17+Assumptions!$B$23/($F10*Assumptions!$B$25)*Assumptions!$B$17,Assumptions!$B$22*Assumptions!$B$27*($F10/100)*Assumptions!$B$18+Assumptions!$B$23*Assumptions!$B$27*($F10*Assumptions!$B$26/100)*Assumptions!$B$19))*4) -> 466424.24 | P10: =IF(ISBLANK(Cars!$E$9),"",(IF($B10="ICE",Assumptions!$B$30,Assumptions!$B$31)*4)+($E10*IF($B10="ICE",Assumptions!$B$32,Assumptions!$B$33)*(1-(1-Assumptions!$B$34)^4)/Assumptions!$B$34)) -> 214291.67 | Q10: =IF(ISBLANK(Cars!$E$9),"",Assumptions!$B$12*(N10-Assumptions!$B$13)*48) -> 585939.94 | R10: =IF(ISBLANK(Cars!$E$9),"",N10*48+$E10*Assumptions!$B$6+O10+P10) -> 2985228.5 | S10: =IF(ISBLANK(Cars!$E$9),"",R10-Q10) -> 2399288.6 | T10: =IF(ISBLANK(Cars!$E$9),"",S10/(Assumptions!$B$24*IF($B10="EV",Assumptions!$B$27,1)*4)) -> 49.985179 | U10: =IF(ISBLANK(Cars!$E$9),"",PMT(Assumptions!$B$5/12,60,-$E10,$E10*Assumptions!$B$6)) -> 37217.331 | V10: =IF(ISBLANK(Cars!$E$9),"",(IF($B10="ICE",Assumptions!$B$22/$F10*Assumptions!$B$17+Assumptions!$B$23/($F10*Assumptions!$B$25)*Assumptions!$B$17,Assumptions!$B$22*Assumptions!$B$27*($F10/100)*Assumptions!$B$18+Assumptions!$B$23*Assumptions!$B$27*($F10*Assumptions!$B$26/100)*Assumptions!$B$19))*5) -> 583030.3 | W10: =IF(ISBLANK(Cars!$E$9),"",(IF($B10="ICE",Assumptions!$B$30,Assumptions!$B$31)*5)+($E10*IF($B10="ICE",Assumptions!$B$32,Assumptions!$B$33)*(1-(1-Assumptions!$B$34)^5)/Assumptions!$B$34)) -> 252497.92 | X10: =IF(ISBLANK(Cars!$E$9),"",Assumptions!$B$12*(U10-Assumptions!$B$13)*60) -> 603108.44 | Y10: =IF(ISBLANK(Cars!$E$9),"",U10*60+$E10*Assumptions!$B$6+V10+W10) -> 3255068.1 | Z10: =IF(ISBLANK(Cars!$E$9),"",Y10-X10) -> 2651959.7 | AA10: =IF(ISBLANK(Cars!$E$9),"",Z10/(Assumptions!$B$24*IF($B10="EV",Assumptions!$B$27,1)*5)) -> 44.199328 | AB10: =IF(ISBLANK(Cars!$E$9),"",RANK(L10,$L$6:$L$31,1)) -> 9 | AC10: =IF(ISBLANK(Cars!$E$9),"",RANK(S10,$S$6:$S$31,1)) -> 10 | AD10: =IF(ISBLANK(Cars!$E$9),"",RANK(Z10,$Z$6:$Z$31,1)) -> 12
A11: 6 | B11: =Cars!B10 -> EV | C11: =Cars!C10 -> Tata Curvv EV | D11: =Cars!D10 -> Accomplished X, 55kWh | E11: =Cars!E10 -> 1775000 | F11: =Cars!F10 -> 14 | G11: =IF(ISBLANK(Cars!$E$10),"",PMT(Assumptions!$B$5/12,36,-$E11,$E11*Assumptions!$B$6)) -> 53025.998 | H11: =IF(ISBLANK(Cars!$E$10),"",(IF($B11="ICE",Assumptions!$B$22/$F11*Assumptions!$B$17+Assumptions!$B$23/($F11*Assumptions!$B$25)*Assumptions!$B$17,Assumptions!$B$22*Assumptions!$B$27*($F11/100)*Assumptions!$B$18+Assumptions!$B$23*Assumptions!$B$27*($F11*Assumptions!$B$26/100)*Assumptions!$B$19))*3) -> 65520 | I11: =IF(ISBLANK(Cars!$E$10),"",(IF($B11="ICE",Assumptions!$B$30,Assumptions!$B$31)*3)+($E11*IF($B11="ICE",Assumptions!$B$32,Assumptions!$B$33)*(1-(1-Assumptions!$B$34)^3)/Assumptions!$B$34)) -> 187015.12 | J11: =IF(ISBLANK(Cars!$E$10),"",Assumptions!$B$12*(G11-Assumptions!$B$13)*36) -> 539428.01 | K11: =IF(ISBLANK(Cars!$E$10),"",G11*36+$E11*Assumptions!$B$6+H11+I11) -> 2338971.1 | L11: =IF(ISBLANK(Cars!$E$10),"",K11-J11) -> 1799543 | M11: =IF(ISBLANK(Cars!$E$10),"",L11/(Assumptions!$B$24*IF($B11="EV",Assumptions!$B$27,1)*3)) -> 49.987307 | N11: =IF(ISBLANK(Cars!$E$10),"",PMT(Assumptions!$B$5/12,48,-$E11,$E11*Assumptions!$B$6)) -> 41995.894 | O11: =IF(ISBLANK(Cars!$E$10),"",(IF($B11="ICE",Assumptions!$B$22/$F11*Assumptions!$B$17+Assumptions!$B$23/($F11*Assumptions!$B$25)*Assumptions!$B$17,Assumptions!$B$22*Assumptions!$B$27*($F11/100)*Assumptions!$B$18+Assumptions!$B$23*Assumptions!$B$27*($F11*Assumptions!$B$26/100)*Assumptions!$B$19))*4) -> 87360 | P11: =IF(ISBLANK(Cars!$E$10),"",(IF($B11="ICE",Assumptions!$B$30,Assumptions!$B$31)*4)+($E11*IF($B11="ICE",Assumptions!$B$32,Assumptions!$B$33)*(1-(1-Assumptions!$B$34)^4)/Assumptions!$B$34)) -> 232937.86 | Q11: =IF(ISBLANK(Cars!$E$10),"",Assumptions!$B$12*(N11-Assumptions!$B$13)*48) -> 554050.5 | R11: =IF(ISBLANK(Cars!$E$10),"",N11*48+$E11*Assumptions!$B$6+O11+P11) -> 2513600.8 | S11: =IF(ISBLANK(Cars!$E$10),"",R11-Q11) -> 1959550.2 | T11: =IF(ISBLANK(Cars!$E$10),"",S11/(Assumptions!$B$24*IF($B11="EV",Assumptions!$B$27,1)*4)) -> 40.823964 | U11: =IF(ISBLANK(Cars!$E$10),"",PMT(Assumptions!$B$5/12,60,-$E11,$E11*Assumptions!$B$6)) -> 35421.321 | V11: =IF(ISBLANK(Cars!$E$10),"",(IF($B11="ICE",Assumptions!$B$22/$F11*Assumptions!$B$17+Assumptions!$B$23/($F11*Assumptions!$B$25)*Assumptions!$B$17,Assumptions!$B$22*Assumptions!$B$27*($F11/100)*Assumptions!$B$18+Assumptions!$B$23*Assumptions!$B$27*($F11*Assumptions!$B$26/100)*Assumptions!$B$19))*5) -> 109200 | W11: =IF(ISBLANK(Cars!$E$10),"",(IF($B11="ICE",Assumptions!$B$30,Assumptions!$B$31)*5)+($E11*IF($B11="ICE",Assumptions!$B$32,Assumptions!$B$33)*(1-(1-Assumptions!$B$34)^5)/Assumptions!$B$34)) -> 272647.18 | X11: =IF(ISBLANK(Cars!$E$10),"",Assumptions!$B$12*(U11-Assumptions!$B$13)*60) -> 569487.12 | Y11: =IF(ISBLANK(Cars!$E$10),"",U11*60+$E11*Assumptions!$B$6+V11+W11) -> 2684626.4 | Z11: =IF(ISBLANK(Cars!$E$10),"",Y11-X11) -> 2115139.3 | AA11: =IF(ISBLANK(Cars!$E$10),"",Z11/(Assumptions!$B$24*IF($B11="EV",Assumptions!$B$27,1)*5)) -> 35.252322 | AB11: =IF(ISBLANK(Cars!$E$10),"",RANK(L11,$L$6:$L$31,1)) -> 3 | AC11: =IF(ISBLANK(Cars!$E$10),"",RANK(S11,$S$6:$S$31,1)) -> 3 | AD11: =IF(ISBLANK(Cars!$E$10),"",RANK(Z11,$Z$6:$Z$31,1)) -> 2
A12: 7 | B12: =Cars!B11 -> EV | C12: =Cars!C11 -> Hyundai Creta Electric | D12: =Cars!D11 -> Excellence, 42kWh (360° cam) | E12: =Cars!E11 -> 2250000 | F12: =Cars!F11 -> 13.5 | G12: =IF(ISBLANK(Cars!$E$11),"",PMT(Assumptions!$B$5/12,36,-$E12,$E12*Assumptions!$B$6)) -> 67216.054 | H12: =IF(ISBLANK(Cars!$E$11),"",(IF($B12="ICE",Assumptions!$B$22/$F12*Assumptions!$B$17+Assumptions!$B$23/($F12*Assumptions!$B$25)*Assumptions!$B$17,Assumptions!$B$22*Assumptions!$B$27*($F12/100)*Assumptions!$B$18+Assumptions!$B$23*Assumptions!$B$27*($F12*Assumptions!$B$26/100)*Assumptions!$B$19))*3) -> 63180 | I12: =IF(ISBLANK(Cars!$E$11),"",(IF($B12="ICE",Assumptions!$B$30,Assumptions!$B$31)*3)+($E12*IF($B12="ICE",Assumptions!$B$32,Assumptions!$B$33)*(1-(1-Assumptions!$B$34)^3)/Assumptions!$B$34)) -> 233448.75 | J12: =IF(ISBLANK(Cars!$E$11),"",Assumptions!$B$12*(G12-Assumptions!$B$13)*36) -> 698810.72 | K12: =IF(ISBLANK(Cars!$E$11),"",G12*36+$E12*Assumptions!$B$6+H12+I12) -> 2941406.7 | L12: =IF(ISBLANK(Cars!$E$11),"",K12-J12) -> 2242596 | M12: =IF(ISBLANK(Cars!$E$11),"",L12/(Assumptions!$B$24*IF($B12="EV",Assumptions!$B$27,1)*3)) -> 62.294333 | N12: =IF(ISBLANK(Cars!$E$11),"",PMT(Assumptions!$B$5/12,48,-$E12,$E12*Assumptions!$B$6)) -> 53234.231 | O12: =IF(ISBLANK(Cars!$E$11),"",(IF($B12="ICE",Assumptions!$B$22/$F12*Assumptions!$B$17+Assumptions!$B$23/($F12*Assumptions!$B$25)*Assumptions!$B$17,Assumptions!$B$22*Assumptions!$B$27*($F12/100)*Assumptions!$B$18+Assumptions!$B$23*Assumptions!$B$27*($F12*Assumptions!$B$26/100)*Assumptions!$B$19))*4) -> 84240 | P12: =IF(ISBLANK(Cars!$E$11),"",(IF($B12="ICE",Assumptions!$B$30,Assumptions!$B$31)*4)+($E12*IF($B12="ICE",Assumptions!$B$32,Assumptions!$B$33)*(1-(1-Assumptions!$B$34)^4)/Assumptions!$B$34)) -> 290456.44 | Q12: =IF(ISBLANK(Cars!$E$11),"",Assumptions!$B$12*(N12-Assumptions!$B$13)*48) -> 722355.85 | R12: =IF(ISBLANK(Cars!$E$11),"",N12*48+$E12*Assumptions!$B$6+O12+P12) -> 3154939.5 | S12: =IF(ISBLANK(Cars!$E$11),"",R12-Q12) -> 2432583.7 | T12: =IF(ISBLANK(Cars!$E$11),"",S12/(Assumptions!$B$24*IF($B12="EV",Assumptions!$B$27,1)*4)) -> 50.678827 | U12: =IF(ISBLANK(Cars!$E$11),"",PMT(Assumptions!$B$5/12,60,-$E12,$E12*Assumptions!$B$6)) -> 44900.266 | V12: =IF(ISBLANK(Cars!$E$11),"",(IF($B12="ICE",Assumptions!$B$22/$F12*Assumptions!$B$17+Assumptions!$B$23/($F12*Assumptions!$B$25)*Assumptions!$B$17,Assumptions!$B$22*Assumptions!$B$27*($F12/100)*Assumptions!$B$18+Assumptions!$B$23*Assumptions!$B$27*($F12*Assumptions!$B$26/100)*Assumptions!$B$19))*5) -> 105300 | W12: =IF(ISBLANK(Cars!$E$11),"",(IF($B12="ICE",Assumptions!$B$30,Assumptions!$B$31)*5)+($E12*IF($B12="ICE",Assumptions!$B$32,Assumptions!$B$33)*(1-(1-Assumptions!$B$34)^5)/Assumptions!$B$34)) -> 339587.97 | X12: =IF(ISBLANK(Cars!$E$11),"",Assumptions!$B$12*(U12-Assumptions!$B$13)*60) -> 746932.97 | Y12: =IF(ISBLANK(Cars!$E$11),"",U12*60+$E12*Assumptions!$B$6+V12+W12) -> 3363903.9 | Z12: =IF(ISBLANK(Cars!$E$11),"",Y12-X12) -> 2616970.9 | AA12: =IF(ISBLANK(Cars!$E$11),"",Z12/(Assumptions!$B$24*IF($B12="EV",Assumptions!$B$27,1)*5)) -> 43.616182 | AB12: =IF(ISBLANK(Cars!$E$11),"",RANK(L12,$L$6:$L$31,1)) -> 12 | AC12: =IF(ISBLANK(Cars!$E$11),"",RANK(S12,$S$6:$S$31,1)) -> 12 | AD12: =IF(ISBLANK(Cars!$E$11),"",RANK(Z12,$Z$6:$Z$31,1)) -> 9
A13: 8 | B13: =Cars!B12 -> EV | C13: =Cars!C12 -> Hyundai Creta Electric | D13: =Cars!D12 -> Excellence LR, 51.4kWh (360° cam) | E13: =Cars!E12 -> 2530000 | F13: =Cars!F12 -> 13.9 | G13: =IF(ISBLANK(Cars!$E$12),"",PMT(Assumptions!$B$5/12,36,-$E13,$E13*Assumptions!$B$6)) -> 75580.719 | H13: =IF(ISBLANK(Cars!$E$12),"",(IF($B13="ICE",Assumptions!$B$22/$F13*Assumptions!$B$17+Assumptions!$B$23/($F13*Assumptions!$B$25)*Assumptions!$B$17,Assumptions!$B$22*Assumptions!$B$27*($F13/100)*Assumptions!$B$18+Assumptions!$B$23*Assumptions!$B$27*($F13*Assumptions!$B$26/100)*Assumptions!$B$19))*3) -> 65052 | I13: =IF(ISBLANK(Cars!$E$12),"",(IF($B13="ICE",Assumptions!$B$30,Assumptions!$B$31)*3)+($E13*IF($B13="ICE",Assumptions!$B$32,Assumptions!$B$33)*(1-(1-Assumptions!$B$34)^3)/Assumptions!$B$34)) -> 260820.15 | J13: =IF(ISBLANK(Cars!$E$12),"",Assumptions!$B$12*(G13-Assumptions!$B$13)*36) -> 792762.63 | K13: =IF(ISBLANK(Cars!$E$12),"",G13*36+$E13*Assumptions!$B$6+H13+I13) -> 3299778 | L13: =IF(ISBLANK(Cars!$E$12),"",K13-J13) -> 2507015.4 | M13: =IF(ISBLANK(Cars!$E$12),"",L13/(Assumptions!$B$24*IF($B13="EV",Assumptions!$B$27,1)*3)) -> 69.639316 | N13: =IF(ISBLANK(Cars!$E$12),"",PMT(Assumptions!$B$5/12,48,-$E13,$E13*Assumptions!$B$6)) -> 59858.936 | O13: =IF(ISBLANK(Cars!$E$12),"",(IF($B13="ICE",Assumptions!$B$22/$F13*Assumptions!$B$17+Assumptions!$B$23/($F13*Assumptions!$B$25)*Assumptions!$B$17,Assumptions!$B$22*Assumptions!$B$27*($F13/100)*Assumptions!$B$18+Assumptions!$B$23*Assumptions!$B$27*($F13*Assumptions!$B$26/100)*Assumptions!$B$19))*4) -> 86736 | P13: =IF(ISBLANK(Cars!$E$12),"",(IF($B13="ICE",Assumptions!$B$30,Assumptions!$B$31)*4)+($E13*IF($B13="ICE",Assumptions!$B$32,Assumptions!$B$33)*(1-(1-Assumptions!$B$34)^4)/Assumptions!$B$34)) -> 324362.13 | Q13: =IF(ISBLANK(Cars!$E$12),"",Assumptions!$B$12*(N13-Assumptions!$B$13)*48) -> 821567.42 | R13: =IF(ISBLANK(Cars!$E$12),"",N13*48+$E13*Assumptions!$B$6+O13+P13) -> 3537327 | S13: =IF(ISBLANK(Cars!$E$12),"",R13-Q13) -> 2715759.6 | T13: =IF(ISBLANK(Cars!$E$12),"",S13/(Assumptions!$B$24*IF($B13="EV",Assumptions!$B$27,1)*4)) -> 56.578325 | U13: =IF(ISBLANK(Cars!$E$12),"",PMT(Assumptions!$B$5/12,60,-$E13,$E13*Assumptions!$B$6)) -> 50487.854 | V13: =IF(ISBLANK(Cars!$E$12),"",(IF($B13="ICE",Assumptions!$B$22/$F13*Assumptions!$B$17+Assumptions!$B$23/($F13*Assumptions!$B$25)*Assumptions!$B$17,Assumptions!$B$22*Assumptions!$B$27*($F13/100)*Assumptions!$B$18+Assumptions!$B$23*Assumptions!$B$27*($F13*Assumptions!$B$26/100)*Assumptions!$B$19))*5) -> 108420 | W13: =IF(ISBLANK(Cars!$E$12),"",(IF($B13="ICE",Assumptions!$B$30,Assumptions!$B$31)*5)+($E13*IF($B13="ICE",Assumptions!$B$32,Assumptions!$B$33)*(1-(1-Assumptions!$B$34)^5)/Assumptions!$B$34)) -> 379047.81 | X13: =IF(ISBLANK(Cars!$E$12),"",Assumptions!$B$12*(U13-Assumptions!$B$13)*60) -> 851532.63 | Y13: =IF(ISBLANK(Cars!$E$12),"",U13*60+$E13*Assumptions!$B$6+V13+W13) -> 3769739.1 | Z13: =IF(ISBLANK(Cars!$E$12),"",Y13-X13) -> 2918206.4 | AA13: =IF(ISBLANK(Cars!$E$12),"",Z13/(Assumptions!$B$24*IF($B13="EV",Assumptions!$B$27,1)*5)) -> 48.636774 | AB13: =IF(ISBLANK(Cars!$E$12),"",RANK(L13,$L$6:$L$31,1)) -> 14 | AC13: =IF(ISBLANK(Cars!$E$12),"",RANK(S13,$S$6:$S$31,1)) -> 14 | AD13: =IF(ISBLANK(Cars!$E$12),"",RANK(Z13,$Z$6:$Z$31,1)) -> 14
A14: 9 | B14: =Cars!B13 -> EV | C14: =Cars!C13 -> MG Windsor EV | D14: =Cars!D13 -> Essence Pro, 52.9kWh (360° cam) | E14: =Cars!E13 -> 1980000 | F14: =Cars!F13 -> 13.2 | G14: =IF(ISBLANK(Cars!$E$13),"",PMT(Assumptions!$B$5/12,36,-$E14,$E14*Assumptions!$B$6)) -> 59150.128 | H14: =IF(ISBLANK(Cars!$E$13),"",(IF($B14="ICE",Assumptions!$B$22/$F14*Assumptions!$B$17+Assumptions!$B$23/($F14*Assumptions!$B$25)*Assumptions!$B$17,Assumptions!$B$22*Assumptions!$B$27*($F14/100)*Assumptions!$B$18+Assumptions!$B$23*Assumptions!$B$27*($F14*Assumptions!$B$26/100)*Assumptions!$B$19))*3) -> 61776 | I14: =IF(ISBLANK(Cars!$E$13),"",(IF($B14="ICE",Assumptions!$B$30,Assumptions!$B$31)*3)+($E14*IF($B14="ICE",Assumptions!$B$32,Assumptions!$B$33)*(1-(1-Assumptions!$B$34)^3)/Assumptions!$B$34)) -> 207054.9 | J14: =IF(ISBLANK(Cars!$E$13),"",Assumptions!$B$12*(G14-Assumptions!$B$13)*36) -> 608214.23 | K14: =IF(ISBLANK(Cars!$E$13),"",G14*36+$E14*Assumptions!$B$6+H14+I14) -> 2596235.5 | L14: =IF(ISBLANK(Cars!$E$13),"",K14-J14) -> 1988021.3 | M14: =IF(ISBLANK(Cars!$E$13),"",L14/(Assumptions!$B$24*IF($B14="EV",Assumptions!$B$27,1)*3)) -> 55.222813 | N14: =IF(ISBLANK(Cars!$E$13),"",PMT(Assumptions!$B$5/12,48,-$E14,$E14*Assumptions!$B$6)) -> 46846.124 | O14: =IF(ISBLANK(Cars!$E$13),"",(IF($B14="ICE",Assumptions!$B$22/$F14*Assumptions!$B$17+Assumptions!$B$23/($F14*Assumptions!$B$25)*Assumptions!$B$17,Assumptions!$B$22*Assumptions!$B$27*($F14/100)*Assumptions!$B$18+Assumptions!$B$23*Assumptions!$B$27*($F14*Assumptions!$B$26/100)*Assumptions!$B$19))*4) -> 82368 | P14: =IF(ISBLANK(Cars!$E$13),"",(IF($B14="ICE",Assumptions!$B$30,Assumptions!$B$31)*4)+($E14*IF($B14="ICE",Assumptions!$B$32,Assumptions!$B$33)*(1-(1-Assumptions!$B$34)^4)/Assumptions!$B$34)) -> 257761.67 | Q14: =IF(ISBLANK(Cars!$E$13),"",Assumptions!$B$12*(N14-Assumptions!$B$13)*48) -> 626687.55 | R14: =IF(ISBLANK(Cars!$E$13),"",N14*48+$E14*Assumptions!$B$6+O14+P14) -> 2786743.6 | S14: =IF(ISBLANK(Cars!$E$13),"",R14-Q14) -> 2160056.1 | T14: =IF(ISBLANK(Cars!$E$13),"",S14/(Assumptions!$B$24*IF($B14="EV",Assumptions!$B$27,1)*4)) -> 45.001168 | U14: =IF(ISBLANK(Cars!$E$13),"",PMT(Assumptions!$B$5/12,60,-$E14,$E14*Assumptions!$B$6)) -> 39512.234 | V14: =IF(ISBLANK(Cars!$E$13),"",(IF($B14="ICE",Assumptions!$B$22/$F14*Assumptions!$B$17+Assumptions!$B$23/($F14*Assumptions!$B$25)*Assumptions!$B$17,Assumptions!$B$22*Assumptions!$B$27*($F14/100)*Assumptions!$B$18+Assumptions!$B$23*Assumptions!$B$27*($F14*Assumptions!$B$26/100)*Assumptions!$B$19))*5) -> 102960 | W14: =IF(ISBLANK(Cars!$E$13),"",(IF($B14="ICE",Assumptions!$B$30,Assumptions!$B$31)*5)+($E14*IF($B14="ICE",Assumptions!$B$32,Assumptions!$B$33)*(1-(1-Assumptions!$B$34)^5)/Assumptions!$B$34)) -> 301537.42 | X14: =IF(ISBLANK(Cars!$E$13),"",Assumptions!$B$12*(U14-Assumptions!$B$13)*60) -> 646069.01 | Y14: =IF(ISBLANK(Cars!$E$13),"",U14*60+$E14*Assumptions!$B$6+V14+W14) -> 2973231.4 | Z14: =IF(ISBLANK(Cars!$E$13),"",Y14-X14) -> 2327162.4 | AA14: =IF(ISBLANK(Cars!$E$13),"",Z14/(Assumptions!$B$24*IF($B14="EV",Assumptions!$B$27,1)*5)) -> 38.78604 | AB14: =IF(ISBLANK(Cars!$E$13),"",RANK(L14,$L$6:$L$31,1)) -> 6 | AC14: =IF(ISBLANK(Cars!$E$13),"",RANK(S14,$S$6:$S$31,1)) -> 6 | AD14: =IF(ISBLANK(Cars!$E$13),"",RANK(Z14,$Z$6:$Z$31,1)) -> 6
A15: 10 | B15: =Cars!B14 -> EV | C15: =Cars!C14 -> Mahindra XUV 3XO EV | D15: =Cars!D14 -> AX7L (top, 360° cam standard) | E15: =Cars!E14 -> 1643000 | F15: =Cars!F14 -> 13.8 | G15: =IF(ISBLANK(Cars!$E$14),"",PMT(Assumptions!$B$5/12,36,-$E15,$E15*Assumptions!$B$6)) -> 49082.656 | H15: =IF(ISBLANK(Cars!$E$14),"",(IF($B15="ICE",Assumptions!$B$22/$F15*Assumptions!$B$17+Assumptions!$B$23/($F15*Assumptions!$B$25)*Assumptions!$B$17,Assumptions!$B$22*Assumptions!$B$27*($F15/100)*Assumptions!$B$18+Assumptions!$B$23*Assumptions!$B$27*($F15*Assumptions!$B$26/100)*Assumptions!$B$19))*3) -> 64584 | I15: =IF(ISBLANK(Cars!$E$14),"",(IF($B15="ICE",Assumptions!$B$30,Assumptions!$B$31)*3)+($E15*IF($B15="ICE",Assumptions!$B$32,Assumptions!$B$33)*(1-(1-Assumptions!$B$34)^3)/Assumptions!$B$34)) -> 174111.46 | J15: =IF(ISBLANK(Cars!$E$14),"",Assumptions!$B$12*(G15-Assumptions!$B$13)*36) -> 495136.4 | K15: =IF(ISBLANK(Cars!$E$14),"",G15*36+$E15*Assumptions!$B$6+H15+I15) -> 2169971.1 | L15: =IF(ISBLANK(Cars!$E$14),"",K15-J15) -> 1674834.7 | M15: =IF(ISBLANK(Cars!$E$14),"",L15/(Assumptions!$B$24*IF($B15="EV",Assumptions!$B$27,1)*3)) -> 46.523186 | N15: =IF(ISBLANK(Cars!$E$14),"",PMT(Assumptions!$B$5/12,48,-$E15,$E15*Assumptions!$B$6)) -> 38872.819 | O15: =IF(ISBLANK(Cars!$E$14),"",(IF($B15="ICE",Assumptions!$B$22/$F15*Assumptions!$B$17+Assumptions!$B$23/($F15*Assumptions!$B$25)*Assumptions!$B$17,Assumptions!$B$22*Assumptions!$B$27*($F15/100)*Assumptions!$B$18+Assumptions!$B$23*Assumptions!$B$27*($F15*Assumptions!$B$26/100)*Assumptions!$B$19))*4) -> 86112 | P15: =IF(ISBLANK(Cars!$E$14),"",(IF($B15="ICE",Assumptions!$B$30,Assumptions!$B$31)*4)+($E15*IF($B15="ICE",Assumptions!$B$32,Assumptions!$B$33)*(1-(1-Assumptions!$B$34)^4)/Assumptions!$B$34)) -> 216953.75 | Q15: =IF(ISBLANK(Cars!$E$14),"",Assumptions!$B$12*(N15-Assumptions!$B$13)*48) -> 507279.33 | R15: =IF(ISBLANK(Cars!$E$14),"",N15*48+$E15*Assumptions!$B$6+O15+P15) -> 2333261 | S15: =IF(ISBLANK(Cars!$E$14),"",R15-Q15) -> 1825981.7 | T15: =IF(ISBLANK(Cars!$E$14),"",S15/(Assumptions!$B$24*IF($B15="EV",Assumptions!$B$27,1)*4)) -> 38.041286 | U15: =IF(ISBLANK(Cars!$E$14),"",PMT(Assumptions!$B$5/12,60,-$E15,$E15*Assumptions!$B$6)) -> 32787.172 | V15: =IF(ISBLANK(Cars!$E$14),"",(IF($B15="ICE",Assumptions!$B$22/$F15*Assumptions!$B$17+Assumptions!$B$23/($F15*Assumptions!$B$25)*Assumptions!$B$17,Assumptions!$B$22*Assumptions!$B$27*($F15/100)*Assumptions!$B$18+Assumptions!$B$23*Assumptions!$B$27*($F15*Assumptions!$B$26/100)*Assumptions!$B$19))*5) -> 107640 | W15: =IF(ISBLANK(Cars!$E$14),"",(IF($B15="ICE",Assumptions!$B$30,Assumptions!$B$31)*5)+($E15*IF($B15="ICE",Assumptions!$B$32,Assumptions!$B$33)*(1-(1-Assumptions!$B$34)^5)/Assumptions!$B$34)) -> 254044.68 | X15: =IF(ISBLANK(Cars!$E$14),"",Assumptions!$B$12*(U15-Assumptions!$B$13)*60) -> 520175.85 | Y15: =IF(ISBLANK(Cars!$E$14),"",U15*60+$E15*Assumptions!$B$6+V15+W15) -> 2493215 | Z15: =IF(ISBLANK(Cars!$E$14),"",Y15-X15) -> 1973039.1 | AA15: =IF(ISBLANK(Cars!$E$14),"",Z15/(Assumptions!$B$24*IF($B15="EV",Assumptions!$B$27,1)*5)) -> 32.883986 | AB15: =IF(ISBLANK(Cars!$E$14),"",RANK(L15,$L$6:$L$31,1)) -> 1 | AC15: =IF(ISBLANK(Cars!$E$14),"",RANK(S15,$S$6:$S$31,1)) -> 1 | AD15: =IF(ISBLANK(Cars!$E$14),"",RANK(Z15,$Z$6:$Z$31,1)) -> 1
A16: 11 | B16: =Cars!B15 -> EV | C16: =Cars!C15 -> Tata Sierra EV | D16: =Cars!D15 -> Adventure, 63kWh (360° cam trim) | E16: =Cars!E15 -> 2214000 | F16: =Cars!F15 -> 15.4 | G16: =IF(ISBLANK(Cars!$E$15),"",PMT(Assumptions!$B$5/12,36,-$E16,$E16*Assumptions!$B$6)) -> 66140.597 | H16: =IF(ISBLANK(Cars!$E$15),"",(IF($B16="ICE",Assumptions!$B$22/$F16*Assumptions!$B$17+Assumptions!$B$23/($F16*Assumptions!$B$25)*Assumptions!$B$17,Assumptions!$B$22*Assumptions!$B$27*($F16/100)*Assumptions!$B$18+Assumptions!$B$23*Assumptions!$B$27*($F16*Assumptions!$B$26/100)*Assumptions!$B$19))*3) -> 72072 | I16: =IF(ISBLANK(Cars!$E$15),"",(IF($B16="ICE",Assumptions!$B$30,Assumptions!$B$31)*3)+($E16*IF($B16="ICE",Assumptions!$B$32,Assumptions!$B$33)*(1-(1-Assumptions!$B$34)^3)/Assumptions!$B$34)) -> 229929.57 | J16: =IF(ISBLANK(Cars!$E$15),"",Assumptions!$B$12*(G16-Assumptions!$B$13)*36) -> 686731.19 | K16: =IF(ISBLANK(Cars!$E$15),"",G16*36+$E16*Assumptions!$B$6+H16+I16) -> 2904463.1 | L16: =IF(ISBLANK(Cars!$E$15),"",K16-J16) -> 2217731.9 | M16: =IF(ISBLANK(Cars!$E$15),"",L16/(Assumptions!$B$24*IF($B16="EV",Assumptions!$B$27,1)*3)) -> 61.603663 | N16: =IF(ISBLANK(Cars!$E$15),"",PMT(Assumptions!$B$5/12,48,-$E16,$E16*Assumptions!$B$6)) -> 52382.484 | O16: =IF(ISBLANK(Cars!$E$15),"",(IF($B16="ICE",Assumptions!$B$22/$F16*Assumptions!$B$17+Assumptions!$B$23/($F16*Assumptions!$B$25)*Assumptions!$B$17,Assumptions!$B$22*Assumptions!$B$27*($F16/100)*Assumptions!$B$18+Assumptions!$B$23*Assumptions!$B$27*($F16*Assumptions!$B$26/100)*Assumptions!$B$19))*4) -> 96096 | P16: =IF(ISBLANK(Cars!$E$15),"",(IF($B16="ICE",Assumptions!$B$30,Assumptions!$B$31)*4)+($E16*IF($B16="ICE",Assumptions!$B$32,Assumptions!$B$33)*(1-(1-Assumptions!$B$34)^4)/Assumptions!$B$34)) -> 286097.13 | Q16: =IF(ISBLANK(Cars!$E$15),"",Assumptions!$B$12*(N16-Assumptions!$B$13)*48) -> 709600.08 | R16: =IF(ISBLANK(Cars!$E$15),"",N16*48+$E16*Assumptions!$B$6+O16+P16) -> 3117952.4 | S16: =IF(ISBLANK(Cars!$E$15),"",R16-Q16) -> 2408352.3 | T16: =IF(ISBLANK(Cars!$E$15),"",S16/(Assumptions!$B$24*IF($B16="EV",Assumptions!$B$27,1)*4)) -> 50.174006 | U16: =IF(ISBLANK(Cars!$E$15),"",PMT(Assumptions!$B$5/12,60,-$E16,$E16*Assumptions!$B$6)) -> 44181.861 | V16: =IF(ISBLANK(Cars!$E$15),"",(IF($B16="ICE",Assumptions!$B$22/$F16*Assumptions!$B$17+Assumptions!$B$23/($F16*Assumptions!$B$25)*Assumptions!$B$17,Assumptions!$B$22*Assumptions!$B$27*($F16/100)*Assumptions!$B$18+Assumptions!$B$23*Assumptions!$B$27*($F16*Assumptions!$B$26/100)*Assumptions!$B$19))*5) -> 120120 | W16: =IF(ISBLANK(Cars!$E$15),"",(IF($B16="ICE",Assumptions!$B$30,Assumptions!$B$31)*5)+($E16*IF($B16="ICE",Assumptions!$B$32,Assumptions!$B$33)*(1-(1-Assumptions!$B$34)^5)/Assumptions!$B$34)) -> 334514.56 | X16: =IF(ISBLANK(Cars!$E$15),"",Assumptions!$B$12*(U16-Assumptions!$B$13)*60) -> 733484.44 | Y16: =IF(ISBLANK(Cars!$E$15),"",U16*60+$E16*Assumptions!$B$6+V16+W16) -> 3326946.2 | Z16: =IF(ISBLANK(Cars!$E$15),"",Y16-X16) -> 2593461.8 | AA16: =IF(ISBLANK(Cars!$E$15),"",Z16/(Assumptions!$B$24*IF($B16="EV",Assumptions!$B$27,1)*5)) -> 43.224363 | AB16: =IF(ISBLANK(Cars!$E$15),"",RANK(L16,$L$6:$L$31,1)) -> 11 | AC16: =IF(ISBLANK(Cars!$E$15),"",RANK(S16,$S$6:$S$31,1)) -> 11 | AD16: =IF(ISBLANK(Cars!$E$15),"",RANK(Z16,$Z$6:$Z$31,1)) -> 8
A17: 12 | B17: =Cars!B16 -> EV | C17: =Cars!C16 -> Tata Nexon EV | D17: =Cars!D16 -> Empowered+ A, 45kWh LR (360° cam) — ADDED | E17: =Cars!E16 -> 1946000 | F17: =Cars!F16 -> 14.1 | G17: =IF(ISBLANK(Cars!$E$16),"",PMT(Assumptions!$B$5/12,36,-$E17,$E17*Assumptions!$B$6)) -> 58134.418 | H17: =IF(ISBLANK(Cars!$E$16),"",(IF($B17="ICE",Assumptions!$B$22/$F17*Assumptions!$B$17+Assumptions!$B$23/($F17*Assumptions!$B$25)*Assumptions!$B$17,Assumptions!$B$22*Assumptions!$B$27*($F17/100)*Assumptions!$B$18+Assumptions!$B$23*Assumptions!$B$27*($F17*Assumptions!$B$26/100)*Assumptions!$B$19))*3) -> 65988 | I17: =IF(ISBLANK(Cars!$E$16),"",(IF($B17="ICE",Assumptions!$B$30,Assumptions!$B$31)*3)+($E17*IF($B17="ICE",Assumptions!$B$32,Assumptions!$B$33)*(1-(1-Assumptions!$B$34)^3)/Assumptions!$B$34)) -> 203731.23 | J17: =IF(ISBLANK(Cars!$E$16),"",Assumptions!$B$12*(G17-Assumptions!$B$13)*36) -> 596805.79 | K17: =IF(ISBLANK(Cars!$E$16),"",G17*36+$E17*Assumptions!$B$6+H17+I17) -> 2557158.3 | L17: =IF(ISBLANK(Cars!$E$16),"",K17-J17) -> 1960352.5 | M17: =IF(ISBLANK(Cars!$E$16),"",L17/(Assumptions!$B$24*IF($B17="EV",Assumptions!$B$27,1)*3)) -> 54.454236 | N17: =IF(ISBLANK(Cars!$E$16),"",PMT(Assumptions!$B$5/12,48,-$E17,$E17*Assumptions!$B$6)) -> 46041.695 | O17: =IF(ISBLANK(Cars!$E$16),"",(IF($B17="ICE",Assumptions!$B$22/$F17*Assumptions!$B$17+Assumptions!$B$23/($F17*Assumptions!$B$25)*Assumptions!$B$17,Assumptions!$B$22*Assumptions!$B$27*($F17/100)*Assumptions!$B$18+Assumptions!$B$23*Assumptions!$B$27*($F17*Assumptions!$B$26/100)*Assumptions!$B$19))*4) -> 87984 | P17: =IF(ISBLANK(Cars!$E$16),"",(IF($B17="ICE",Assumptions!$B$30,Assumptions!$B$31)*4)+($E17*IF($B17="ICE",Assumptions!$B$32,Assumptions!$B$33)*(1-(1-Assumptions!$B$34)^4)/Assumptions!$B$34)) -> 253644.55 | Q17: =IF(ISBLANK(Cars!$E$16),"",Assumptions!$B$12*(N17-Assumptions!$B$13)*48) -> 614640.43 | R17: =IF(ISBLANK(Cars!$E$16),"",N17*48+$E17*Assumptions!$B$6+O17+P17) -> 2746229.9 | S17: =IF(ISBLANK(Cars!$E$16),"",R17-Q17) -> 2131589.5 | T17: =IF(ISBLANK(Cars!$E$16),"",S17/(Assumptions!$B$24*IF($B17="EV",Assumptions!$B$27,1)*4)) -> 44.408114 | U17: =IF(ISBLANK(Cars!$E$16),"",PMT(Assumptions!$B$5/12,60,-$E17,$E17*Assumptions!$B$6)) -> 38833.741 | V17: =IF(ISBLANK(Cars!$E$16),"",(IF($B17="ICE",Assumptions!$B$22/$F17*Assumptions!$B$17+Assumptions!$B$23/($F17*Assumptions!$B$25)*Assumptions!$B$17,Assumptions!$B$22*Assumptions!$B$27*($F17/100)*Assumptions!$B$18+Assumptions!$B$23*Assumptions!$B$27*($F17*Assumptions!$B$26/100)*Assumptions!$B$19))*5) -> 109980 | W17: =IF(ISBLANK(Cars!$E$16),"",(IF($B17="ICE",Assumptions!$B$30,Assumptions!$B$31)*5)+($E17*IF($B17="ICE",Assumptions!$B$32,Assumptions!$B$33)*(1-(1-Assumptions!$B$34)^5)/Assumptions!$B$34)) -> 296745.86 | X17: =IF(ISBLANK(Cars!$E$16),"",Assumptions!$B$12*(U17-Assumptions!$B$13)*60) -> 633367.63 | Y17: =IF(ISBLANK(Cars!$E$16),"",U17*60+$E17*Assumptions!$B$6+V17+W17) -> 2931350.3 | Z17: =IF(ISBLANK(Cars!$E$16),"",Y17-X17) -> 2297982.7 | AA17: =IF(ISBLANK(Cars!$E$16),"",Z17/(Assumptions!$B$24*IF($B17="EV",Assumptions!$B$27,1)*5)) -> 38.299711 | AB17: =IF(ISBLANK(Cars!$E$16),"",RANK(L17,$L$6:$L$31,1)) -> 4 | AC17: =IF(ISBLANK(Cars!$E$16),"",RANK(S17,$S$6:$S$31,1)) -> 4 | AD17: =IF(ISBLANK(Cars!$E$16),"",RANK(Z17,$Z$6:$Z$31,1)) -> 5
A18: 13 | B18: =Cars!B17 -> EV | C18: =Cars!C17 -> Maruti e Vitara | D18: =Cars!D17 -> Alpha, 61kWh (360° cam, ADAS) — ADDED | E18: =Cars!E17 -> 2137000 | F18: =Cars!F17 -> 15.3 | G18: =IF(ISBLANK(Cars!$E$17),"",PMT(Assumptions!$B$5/12,36,-$E18,$E18*Assumptions!$B$6)) -> 63840.314 | H18: =IF(ISBLANK(Cars!$E$17),"",(IF($B18="ICE",Assumptions!$B$22/$F18*Assumptions!$B$17+Assumptions!$B$23/($F18*Assumptions!$B$25)*Assumptions!$B$17,Assumptions!$B$22*Assumptions!$B$27*($F18/100)*Assumptions!$B$18+Assumptions!$B$23*Assumptions!$B$27*($F18*Assumptions!$B$26/100)*Assumptions!$B$19))*3) -> 71604 | I18: =IF(ISBLANK(Cars!$E$17),"",(IF($B18="ICE",Assumptions!$B$30,Assumptions!$B$31)*3)+($E18*IF($B18="ICE",Assumptions!$B$32,Assumptions!$B$33)*(1-(1-Assumptions!$B$34)^3)/Assumptions!$B$34)) -> 222402.43 | J18: =IF(ISBLANK(Cars!$E$17),"",Assumptions!$B$12*(G18-Assumptions!$B$13)*36) -> 660894.41 | K18: =IF(ISBLANK(Cars!$E$17),"",G18*36+$E18*Assumptions!$B$6+H18+I18) -> 2805957.8 | L18: =IF(ISBLANK(Cars!$E$17),"",K18-J18) -> 2145063.3 | M18: =IF(ISBLANK(Cars!$E$17),"",L18/(Assumptions!$B$24*IF($B18="EV",Assumptions!$B$27,1)*3)) -> 59.585093 | N18: =IF(ISBLANK(Cars!$E$17),"",PMT(Assumptions!$B$5/12,48,-$E18,$E18*Assumptions!$B$6)) -> 50560.69 | O18: =IF(ISBLANK(Cars!$E$17),"",(IF($B18="ICE",Assumptions!$B$22/$F18*Assumptions!$B$17+Assumptions!$B$23/($F18*Assumptions!$B$25)*Assumptions!$B$17,Assumptions!$B$22*Assumptions!$B$27*($F18/100)*Assumptions!$B$18+Assumptions!$B$23*Assumptions!$B$27*($F18*Assumptions!$B$26/100)*Assumptions!$B$19))*4) -> 95472 | P18: =IF(ISBLANK(Cars!$E$17),"",(IF($B18="ICE",Assumptions!$B$30,Assumptions!$B$31)*4)+($E18*IF($B18="ICE",Assumptions!$B$32,Assumptions!$B$33)*(1-(1-Assumptions!$B$34)^4)/Assumptions!$B$34)) -> 276773.07 | Q18: =IF(ISBLANK(Cars!$E$17),"",Assumptions!$B$12*(N18-Assumptions!$B$13)*48) -> 682316.89 | R18: =IF(ISBLANK(Cars!$E$17),"",N18*48+$E18*Assumptions!$B$6+O18+P18) -> 3012858.2 | S18: =IF(ISBLANK(Cars!$E$17),"",R18-Q18) -> 2330541.3 | T18: =IF(ISBLANK(Cars!$E$17),"",S18/(Assumptions!$B$24*IF($B18="EV",Assumptions!$B$27,1)*4)) -> 48.552944 | U18: =IF(ISBLANK(Cars!$E$17),"",PMT(Assumptions!$B$5/12,60,-$E18,$E18*Assumptions!$B$6)) -> 42645.274 | V18: =IF(ISBLANK(Cars!$E$17),"",(IF($B18="ICE",Assumptions!$B$22/$F18*Assumptions!$B$17+Assumptions!$B$23/($F18*Assumptions!$B$25)*Assumptions!$B$17,Assumptions!$B$22*Assumptions!$B$27*($F18/100)*Assumptions!$B$18+Assumptions!$B$23*Assumptions!$B$27*($F18*Assumptions!$B$26/100)*Assumptions!$B$19))*5) -> 119340 | W18: =IF(ISBLANK(Cars!$E$17),"",(IF($B18="ICE",Assumptions!$B$30,Assumptions!$B$31)*5)+($E18*IF($B18="ICE",Assumptions!$B$32,Assumptions!$B$33)*(1-(1-Assumptions!$B$34)^5)/Assumptions!$B$34)) -> 323663.11 | X18: =IF(ISBLANK(Cars!$E$17),"",Assumptions!$B$12*(U18-Assumptions!$B$13)*60) -> 704719.54 | Y18: =IF(ISBLANK(Cars!$E$17),"",U18*60+$E18*Assumptions!$B$6+V18+W18) -> 3215419.6 | Z18: =IF(ISBLANK(Cars!$E$17),"",Y18-X18) -> 2510700 | AA18: =IF(ISBLANK(Cars!$E$17),"",Z18/(Assumptions!$B$24*IF($B18="EV",Assumptions!$B$27,1)*5)) -> 41.845001 | AB18: =IF(ISBLANK(Cars!$E$17),"",RANK(L18,$L$6:$L$31,1)) -> 10 | AC18: =IF(ISBLANK(Cars!$E$17),"",RANK(S18,$S$6:$S$31,1)) -> 7 | AD18: =IF(ISBLANK(Cars!$E$17),"",RANK(Z18,$Z$6:$Z$31,1)) -> 7
A19: 14 | B19: =Cars!B18 -> EV | C19: =Cars!C18 -> Kia Syros EV | D19: =Cars!D18 -> HTX+ ER, 51.4kWh (360° cam) — ADDED | E19: =Cars!E18 -> 1950000 | F19: =Cars!F18 -> 13.5 | G19: =IF(ISBLANK(Cars!$E$18),"",PMT(Assumptions!$B$5/12,36,-$E19,$E19*Assumptions!$B$6)) -> 58253.914 | H19: =IF(ISBLANK(Cars!$E$18),"",(IF($B19="ICE",Assumptions!$B$22/$F19*Assumptions!$B$17+Assumptions!$B$23/($F19*Assumptions!$B$25)*Assumptions!$B$17,Assumptions!$B$22*Assumptions!$B$27*($F19/100)*Assumptions!$B$18+Assumptions!$B$23*Assumptions!$B$27*($F19*Assumptions!$B$26/100)*Assumptions!$B$19))*3) -> 63180 | I19: =IF(ISBLANK(Cars!$E$18),"",(IF($B19="ICE",Assumptions!$B$30,Assumptions!$B$31)*3)+($E19*IF($B19="ICE",Assumptions!$B$32,Assumptions!$B$33)*(1-(1-Assumptions!$B$34)^3)/Assumptions!$B$34)) -> 204122.25 | J19: =IF(ISBLANK(Cars!$E$18),"",Assumptions!$B$12*(G19-Assumptions!$B$13)*36) -> 598147.96 | K19: =IF(ISBLANK(Cars!$E$18),"",G19*36+$E19*Assumptions!$B$6+H19+I19) -> 2559443.1 | L19: =IF(ISBLANK(Cars!$E$18),"",K19-J19) -> 1961295.2 | M19: =IF(ISBLANK(Cars!$E$18),"",L19/(Assumptions!$B$24*IF($B19="EV",Assumptions!$B$27,1)*3)) -> 54.480422 | N19: =IF(ISBLANK(Cars!$E$18),"",PMT(Assumptions!$B$5/12,48,-$E19,$E19*Assumptions!$B$6)) -> 46136.334 | O19: =IF(ISBLANK(Cars!$E$18),"",(IF($B19="ICE",Assumptions!$B$22/$F19*Assumptions!$B$17+Assumptions!$B$23/($F19*Assumptions!$B$25)*Assumptions!$B$17,Assumptions!$B$22*Assumptions!$B$27*($F19/100)*Assumptions!$B$18+Assumptions!$B$23*Assumptions!$B$27*($F19*Assumptions!$B$26/100)*Assumptions!$B$19))*4) -> 84240 | P19: =IF(ISBLANK(Cars!$E$18),"",(IF($B19="ICE",Assumptions!$B$30,Assumptions!$B$31)*4)+($E19*IF($B19="ICE",Assumptions!$B$32,Assumptions!$B$33)*(1-(1-Assumptions!$B$34)^4)/Assumptions!$B$34)) -> 254128.91 | Q19: =IF(ISBLANK(Cars!$E$18),"",Assumptions!$B$12*(N19-Assumptions!$B$13)*48) -> 616057.74 | R19: =IF(ISBLANK(Cars!$E$18),"",N19*48+$E19*Assumptions!$B$6+O19+P19) -> 2747912.9 | S19: =IF(ISBLANK(Cars!$E$18),"",R19-Q19) -> 2131855.2 | T19: =IF(ISBLANK(Cars!$E$18),"",S19/(Assumptions!$B$24*IF($B19="EV",Assumptions!$B$27,1)*4)) -> 44.41365 | U19: =IF(ISBLANK(Cars!$E$18),"",PMT(Assumptions!$B$5/12,60,-$E19,$E19*Assumptions!$B$6)) -> 38913.563 | V19: =IF(ISBLANK(Cars!$E$18),"",(IF($B19="ICE",Assumptions!$B$22/$F19*Assumptions!$B$17+Assumptions!$B$23/($F19*Assumptions!$B$25)*Assumptions!$B$17,Assumptions!$B$22*Assumptions!$B$27*($F19/100)*Assumptions!$B$18+Assumptions!$B$23*Assumptions!$B$27*($F19*Assumptions!$B$26/100)*Assumptions!$B$19))*5) -> 105300 | W19: =IF(ISBLANK(Cars!$E$18),"",(IF($B19="ICE",Assumptions!$B$30,Assumptions!$B$31)*5)+($E19*IF($B19="ICE",Assumptions!$B$32,Assumptions!$B$33)*(1-(1-Assumptions!$B$34)^5)/Assumptions!$B$34)) -> 297309.58 | X19: =IF(ISBLANK(Cars!$E$18),"",Assumptions!$B$12*(U19-Assumptions!$B$13)*60) -> 634861.91 | Y19: =IF(ISBLANK(Cars!$E$18),"",U19*60+$E19*Assumptions!$B$6+V19+W19) -> 2932423.4 | Z19: =IF(ISBLANK(Cars!$E$18),"",Y19-X19) -> 2297561.5 | AA19: =IF(ISBLANK(Cars!$E$18),"",Z19/(Assumptions!$B$24*IF($B19="EV",Assumptions!$B$27,1)*5)) -> 38.292691 | AB19: =IF(ISBLANK(Cars!$E$18),"",RANK(L19,$L$6:$L$31,1)) -> 5 | AC19: =IF(ISBLANK(Cars!$E$18),"",RANK(S19,$S$6:$S$31,1)) -> 5 | AD19: =IF(ISBLANK(Cars!$E$18),"",RANK(Z19,$Z$6:$Z$31,1)) -> 4
A20: 15 | B20: =Cars!B19 -> 0 | C20: =Cars!C19 -> 0 | D20: =Cars!D19 -> 0 | E20: =Cars!E19 -> 0 | F20: =Cars!F19 -> 0 | G20: =IF(ISBLANK(Cars!$E$19),"",PMT(Assumptions!$B$5/12,36,-$E20,$E20*Assumptions!$B$6)) | H20: =IF(ISBLANK(Cars!$E$19),"",(IF($B20="ICE",Assumptions!$B$22/$F20*Assumptions!$B$17+Assumptions!$B$23/($F20*Assumptions!$B$25)*Assumptions!$B$17,Assumptions!$B$22*Assumptions!$B$27*($F20/100)*Assumptions!$B$18+Assumptions!$B$23*Assumptions!$B$27*($F20*Assumptions!$B$26/100)*Assumptions!$B$19))*3) | I20: =IF(ISBLANK(Cars!$E$19),"",(IF($B20="ICE",Assumptions!$B$30,Assumptions!$B$31)*3)+($E20*IF($B20="ICE",Assumptions!$B$32,Assumptions!$B$33)*(1-(1-Assumptions!$B$34)^3)/Assumptions!$B$34)) | J20: =IF(ISBLANK(Cars!$E$19),"",Assumptions!$B$12*(G20-Assumptions!$B$13)*36) | K20: =IF(ISBLANK(Cars!$E$19),"",G20*36+$E20*Assumptions!$B$6+H20+I20) | L20: =IF(ISBLANK(Cars!$E$19),"",K20-J20) | M20: =IF(ISBLANK(Cars!$E$19),"",L20/(Assumptions!$B$24*IF($B20="EV",Assumptions!$B$27,1)*3)) | N20: =IF(ISBLANK(Cars!$E$19),"",PMT(Assumptions!$B$5/12,48,-$E20,$E20*Assumptions!$B$6)) | O20: =IF(ISBLANK(Cars!$E$19),"",(IF($B20="ICE",Assumptions!$B$22/$F20*Assumptions!$B$17+Assumptions!$B$23/($F20*Assumptions!$B$25)*Assumptions!$B$17,Assumptions!$B$22*Assumptions!$B$27*($F20/100)*Assumptions!$B$18+Assumptions!$B$23*Assumptions!$B$27*($F20*Assumptions!$B$26/100)*Assumptions!$B$19))*4) | P20: =IF(ISBLANK(Cars!$E$19),"",(IF($B20="ICE",Assumptions!$B$30,Assumptions!$B$31)*4)+($E20*IF($B20="ICE",Assumptions!$B$32,Assumptions!$B$33)*(1-(1-Assumptions!$B$34)^4)/Assumptions!$B$34)) | Q20: =IF(ISBLANK(Cars!$E$19),"",Assumptions!$B$12*(N20-Assumptions!$B$13)*48) | R20: =IF(ISBLANK(Cars!$E$19),"",N20*48+$E20*Assumptions!$B$6+O20+P20) | S20: =IF(ISBLANK(Cars!$E$19),"",R20-Q20) | T20: =IF(ISBLANK(Cars!$E$19),"",S20/(Assumptions!$B$24*IF($B20="EV",Assumptions!$B$27,1)*4)) | U20: =IF(ISBLANK(Cars!$E$19),"",PMT(Assumptions!$B$5/12,60,-$E20,$E20*Assumptions!$B$6)) | V20: =IF(ISBLANK(Cars!$E$19),"",(IF($B20="ICE",Assumptions!$B$22/$F20*Assumptions!$B$17+Assumptions!$B$23/($F20*Assumptions!$B$25)*Assumptions!$B$17,Assumptions!$B$22*Assumptions!$B$27*($F20/100)*Assumptions!$B$18+Assumptions!$B$23*Assumptions!$B$27*($F20*Assumptions!$B$26/100)*Assumptions!$B$19))*5) | W20: =IF(ISBLANK(Cars!$E$19),"",(IF($B20="ICE",Assumptions!$B$30,Assumptions!$B$31)*5)+($E20*IF($B20="ICE",Assumptions!$B$32,Assumptions!$B$33)*(1-(1-Assumptions!$B$34)^5)/Assumptions!$B$34)) | X20: =IF(ISBLANK(Cars!$E$19),"",Assumptions!$B$12*(U20-Assumptions!$B$13)*60) | Y20: =IF(ISBLANK(Cars!$E$19),"",U20*60+$E20*Assumptions!$B$6+V20+W20) | Z20: =IF(ISBLANK(Cars!$E$19),"",Y20-X20) | AA20: =IF(ISBLANK(Cars!$E$19),"",Z20/(Assumptions!$B$24*IF($B20="EV",Assumptions!$B$27,1)*5)) | AB20: =IF(ISBLANK(Cars!$E$19),"",RANK(L20,$L$6:$L$31,1)) | AC20: =IF(ISBLANK(Cars!$E$19),"",RANK(S20,$S$6:$S$31,1)) | AD20: =IF(ISBLANK(Cars!$E$19),"",RANK(Z20,$Z$6:$Z$31,1))
